package exceptionTest;

public class demo2 {
	public static void main(String[] args) {
		method2();
	}

	// 两个异常
	private static void method2() {
		int a = 10;
		int b = 0;
		try {
			System.out.println(a / b);
		} catch (ArithmeticException e) {
			System.out.println("除数不能为0");
		}
		System.out.println("end");
	}

	// 一个异常
	private static void method1() {
		int a = 10;
		int b = 0;
		try {
			System.out.println(a / b);
		} catch (ArithmeticException e) {
			System.out.println("除数不能为0");
		}
		System.out.println("end");
	}
}
